package ua.block06.trainigcod.exceptions.part_I;

/**
 * Created on 22.02.2019.
 *
 * @author Aleks Sidorenko (alek.sidorenko1979@gmail.com).
 * @version $Id$.
 * @since 0.1.
 */
public class App43 {

    public static void main(String[] args) {
        try {
            System.err.print(" 0");
            if (true) {throw new RuntimeException();}
            System.err.print(" 1");
        } catch (RuntimeException e) { // перехватили RuntimeException
            System.err.print(" 2.1");
            try {
                System.err.print(" 2.2");
                if (true) {throw new Error();} // и бросили новый Error
                System.err.print(" 2.3");
            } catch (Throwable t) {            // перехватили Error
                System.err.print(" 2.4");
            }
            System.err.print(" 2.5");
        } catch (Error e) { // хотя есть cath по Error "ниже", но мы в него не попадаем
            System.err.print(" 3");
        }
        System.err.println(" 4");
    }
}
