package ua.block06.trainigcod.exceptions.part_I;

/**
 * Created on 22.02.2019.
 *
 * @author Aleks Sidorenko (alek.sidorenko1979@gmail.com).
 * @version $Id$.
 * @since 0.1.
 */
public class App41 {

    public static void main(String[] args) {
        try {
            System.err.print(" 0");
            if (true) {throw new RuntimeException();}
            System.err.print(" 1");
        } catch (RuntimeException e) { // перехватили RuntimeException
            System.err.print(" 2");
            if (true) {throw e;}       // и бросили ВТОРОЙ раз ЕГО ЖЕ
        }
        System.err.println(" 3");      // пропускаем - опять летит RuntimeException
    }
}
